<Issue id="33751" key="FAB-11999" number="11999" project="10002" reporter="nnao" assignee="nnao" creator="nnao" type="10004" summary="FAB-7264 and FAB-7269 behave tests failed to get a &quot;no_usable_index&quot; response." priority="3" resolution="10000" status="6" created="2018-09-13 18:40:46.0" updated="2019-07-26 10:20:10.0" resolutiondate="2019-07-26 10:20:10.0" votes="0" watches="2" workflowId="45054"> <description><! CDATA I get the following error messages when I execute FAB-7264 and FAB-7269 behave tests. {code} ... When a user queries on the channel "mychannel2" using chaincode named "mycc2" with args  "queryMarbles", "{\\"selector\\":{\\"owner\\":\\"alex\\"}, \\"use_index\\": \\"_design/indexdoc_b ehave_test_v1\\", \\"index_behave_test_v1\\" }"  on "peer0.org1.example.com"                                                # steps/endorser_impl.py:437 4.112s Then a user receives a response containing no_usable_index                                                                                 # steps/endorser_impl.py:905 0.000s     Assertion Failed: Expected response was no_usable_index; received  {"Key":"marble2","Record":{"color":"yellow","docType":"marble","name":"marble2","owner":"alex","size":20}}  {code}  ></description> </Issue>
