<Issue id="36375" key="FAB-13424" number="13424" project="10002" reporter="sambhavdutt" assignee="adnanchoudhury" creator="sambhavdutt" type="10004" summary="Assertion error in daily lte tests, perf_couchdb.test_FAB_3875 in one build." priority="3" resolution="10203" status="6" created="2018-12-21 19:30:26.0" updated="2019-03-19 11:13:30.0" resolutiondate="2018-12-27 19:24:18.0" votes="0" watches="3" workflowId="47906"> <description><! CDATA There was an Assertion error observed in *perf_couchdb.test_FAB_3875_VaryBatchSize* , varyBatchSize for CouchDB performance test failed. This test took 4 hours starting at 7:40 PM which is the usual time for daily lte tests.   Intermittent: No  Branch: release-1.4  Error Snippet:  {code:java} "./runbenchmarks.sh -f parameters_couchdb_daily_CI.sh " 23:46:24                 "varyBatchSize", shell=True, stderr=subprocess.STDOUT, 23:46:24                 stdout=logfile, cwd=tool_directory) 23:46:24         logfile.close() 23:46:24         self.assertEqual(returncode, 0, msg="varyBatchSize for CouchDB " 23:46:24                 "performance test failed. \nPlease check the logfile " 23:46:24 >               +logfile.name+" for more etails.") . AssertionError: varyBatchSize for CouchDB performance test failed. ledger_lte.py:322: AssertionError {code}  This may not be a high priority as there was outage in some on the x nodes which failed other tests too.   *Build Log*  https://logs.hyperledger.org/production/vex-yul-hyp-jenkins-3/fabric-test-daily-lte-release-1.4-x86_64/5/  ></description> </Issue>
