<Issue id="27077" key="STL-1018" number="1018" project="10001" reporter="drozd" assignee="drozd" creator="drozd" type="10004" summary="Fix network connections iteration bug" priority="3" resolution="10000" status="10001" created="2018-01-25 17:20:53.0" updated="2018-01-31 18:48:29.0" resolutiondate="2018-01-31 18:48:29.0" votes="0" watches="1" workflowId="27079"> <description><! CDATA This error message was recently logged: {code:java} File "/usr/lib/python3/dist-packages/sawtooth_validator/networking/interconnect.py", line 1049, in get_connection_id_by_endpoint for connection_id in self._connections: RuntimeError: dictionary changed size during iteration  {code} Â This may be related to a more serious peering bug where a node repeatedly attempts and fails to re-peer.  ></description> </Issue>
