<Issue id="27629" key="INDY-1162" number="1162" project="10303" reporter="michaelwang" creator="michaelwang" type="10004" summary="Exception: NETWORK_NAME must be set in /etc/indy/indy_config.py" priority="3" resolution="10000" status="10001" created="2018-02-12 08:46:07.0" updated="2019-03-29 20:35:10.0" resolutiondate="2019-03-29 20:35:10.0" votes="0" watches="2" workflowId="27630"> <description><! CDATA I install all the packages with pip install.  When I try to start indy CLI, I got this error.  I wonder if this is a bug.  ></description> </Issue>
