<Issue id="40256" key="IS-1284" number="1284" project="10401" reporter="lbendixsen" assignee="vladimirwork" creator="lbendixsen" type="10004" summary="Add NYM (role=STEWARD) request from CLI returns an unusable error message" priority="2" resolution="10000" status="10001" created="2019-05-31 17:08:11.0" updated="2019-08-20 14:27:57.0" resolutiondate="2019-08-20 14:27:57.0" votes="0" watches="3" workflowId="53162"> <description><! CDATA _Environment_: indy-CLI version 1.8.1 connecting to the BuilderNet (indy-node version 1.7.1)  _Steps to Reproduce_: # Connect to pool, open wallet, use TRUSTEE DID # set Auth_rules to require trustee signature for adding a STEWARD NYM to the ledger (SUCCESS) # Use a STEWARD DID # Add a STEWARD NYM to the ledger (fail)-> ledger nym did=NSNGwB2MK7WVoG7CLmHhfy verkey=~PRDkZn9HMSL2MUWKFJLpi9 role=STEWARD  *Transaction response has not been received*  _Expected Behavior_: Error message should indicate what went wrong  _Observed Behavior_: Generic "no response" error message was received.  _Notes_: This isn't the only case that causes the "generic" failure message, I am seeing it more and more in recent builds. Excerpt from the logs on the BuilderNet FoundationBuilder node:  2019-05-31 13:19:03,435|INFO|last_sent_pp_store_helper.py|FoundationBuilder found stored lastSentPrePrepare value b'\{"1": 6,44 ,"2": 6,45 ,"3": 6,44 ,"4": 6,44 }'  2019-05-31 13:19:03,436|INFO|last_sent_pp_store_helper.py|FoundationBuilder found stored lastSentPrePrepare value b'\{"1": 6,44 ,"2": 6,46 ,"3": 6,44 ,"4": 6,44 }'  2019-05-31 13:19:03,488|WARNING|auth_request_validator.py|Request Request: \{'signature': '44GGGvgi1bTjZu7DhYYZ7aJCQQpThxgqvK5pV1jrYmcfcJEGdgd2gwQX7rmPt1gE8BikqnzUgCyusiBj8Ck4CE1q', 'reqId': 1559308742915656000, 'operation': {'dest': 'NSNGwB2MK7WVoG7CLmHhfy', 'verkey': '~PRDkZn9HMSL2MUWKFJLpi9', 'type': '1', 'role': '2'}, 'protocolVersion': 2, 'identifier': '4TMD8bT757JqBnmoCiNCc3'} cannot be authorized by reason: Not enough TRUSTEE signatures  2019-05-31 13:19:03,488|WARNING|replica.py|FoundationBuilder:0 encountered exception UnauthorizedClientRequest('Not enough TRUSTEE signatures',) while processing Request: \{'signature': '44GGGvgi1bTjZu7DhYYZ7aJCQQpThxgqvK5pV1jrYmcfcJEGdgd2gwQX7rmPt1gE8BikqnzUgCyusiBj8Ck4CE1q', 'reqId': 1559308742915656000, 'operation': {'dest': 'NSNGwB2MK7WVoG7CLmHhfy', 'verkey': '~PRDkZn9HMSL2MUWKFJLpi9', 'type': '1', 'role': '2'}, 'protocolVersion': 2, 'identifier': '4TMD8bT757JqBnmoCiNCc3'}, will reject  2019-05-31 13:19:03,509|INFO|last_sent_pp_store_helper.py|FoundationBuilder found stored lastSentPrePrepare value b'\{"1": 6,44 ,"2": 6,46 ,"3": 6,44 ,"4": 6,45 }'  2019-05-31 13:19:03,550|INFO|last_sent_pp_store_helper.py|FoundationBuilder found stored lastSentPrePrepare value b'\{"1": 6,45 ,"2": 6,46 ,"3": 6,44 ,"4": 6,45 }'  ></description> </Issue>
